<?xml version="1.0" ?>
<robot name="robot_sim">

    <material name="black">
        <color rgba="0.15 0.15 0.15 1.0"/>
    </material>
    <material name="silver">
        <color rgba="0.75 0.75 0.75 1.0"/>
    </material>

    <link name="base_link">
        <visual>
            <origin rpy="0 0 0" xyz="0 0 0"/>
            <geometry>
                <mesh filename="package://robot_sim_description/meshes/base_link.stl" scale="0.001 0.001 0.001"/>
            </geometry>
            <material name="silver"/>
        </visual>
        <collision>
            <origin rpy="0 0 0" xyz="0 0 0"/>
            <geometry>
                <mesh filename="package://robot_sim_description/meshes/base_link.stl" scale="0.001 0.001 0.001"/>
            </geometry>
        </collision>
    </link>

    <link name="base_inertia">
        <inertial>
            <origin xyz="0 0 0"/>
            <mass value="2.7"/>
            <inertia ixx="0.0028125" ixy="0.0" ixz="0.0" iyy="0.005625" iyz="0.0" izz="0.0073125"/>
        </inertial>
    </link>
    <joint name="base_link_to_base_inertia" type="fixed">
        <parent link="base_link"/>
        <child link="base_inertia"/>
        <origin rpy="0 0 0" xyz="0 0 0"/>
    </joint>

    <gazebo reference="base_link">
        <material>Gazebo/Grey</material>
    </gazebo>


    <joint name="lf_hipp_joint" type="revolute">
        <axis xyz="1 0 0"/>
        <limit effort="5" lower="-3.14" upper="3.14" velocity="2.5"/>
        <parent link="base_link"/>
        <child link="lf_hipp_link"/>
        <origin rpy="0 0 0" xyz="0.04469 0.04937 0.01767"/>
    </joint>
    <link name="lf_hipp_link">
        <inertial>
            <mass value="0.7"/>
            <inertia ixx="0.0001866" ixy="0.0" ixz="0.0" iyy="0.0001866" iyz="0.0" izz="0.0001866"/>
        </inertial>
        <visual>
            <origin rpy="0 0 0" xyz="0 0 0"/>
            <geometry>
                <mesh filename="package://robot_sim_description/meshes/lf_hipp.stl" scale="0.001 0.001 0.001"/>
            </geometry>
            <material name="silver"/>
        </visual>
        <collision>
            <origin rpy="0 0 0" xyz="0 0 0"/>
            <geometry>
                <mesh filename="package://robot_sim_description/meshes/lf_hipp.stl" scale="0.001 0.001 0.001"/>
            </geometry>
        </collision>
    </link>
    <joint name="lf_up_joint" type="revolute">
        <axis xyz="0 1 0"/>
        <limit effort="5" lower="-3.14" upper="3.14" velocity="2.5"/>
        <parent link="lf_hipp_link"/>
        <child link="lf_up_link"/>
        <origin rpy="0 0 0" xyz="0 0.0266 0"/>
    </joint>
    <link name="lf_up_link">
        <inertial>
            <origin xyz="0 0 -0.03265"/>
            <mass value="0.2"/>
            <inertia ixx="0.0000777" ixy="0.0" ixz="0.0" iyy="0.0000860" iyz="0.0" izz="0.0000216"/>
        </inertial>
        <visual>
            <origin rpy="0 0 0" xyz="0 0 0"/>
            <geometry>
                <mesh filename="package://robot_sim_description/meshes/lf_up.stl" scale="0.001 0.001 0.001"/>
            </geometry>
            <material name="silver"/>
        </visual>
        <collision>
            <origin rpy="0 0 0" xyz="0 0 0"/>
            <geometry>
                <mesh filename="package://robot_sim_description/meshes/lf_up.stl" scale="0.001 0.001 0.001"/>
            </geometry>
        </collision>
    </link>
    <joint name="lf_low_joint" type="revolute">
        <axis xyz="0 1 0"/>
        <limit effort="5" lower="-3.14" upper="3.14" velocity="2.5"/>
        <parent link="lf_up_link"/>
        <child link="lf_low_link"/>
        <origin rpy="0 0 0" xyz="0 0.0075 -0.0653"/>
    </joint>
    <link name="lf_low_link">
        <inertial>
            <origin xyz="0 0 -0.025"/>
            <mass value="0.2"/>
            <inertia ixx="0.0000483" ixy="0.0" ixz="0.0" iyy="0.0000483" iyz="0.0" izz="0.0000133"/>
        </inertial>
        <visual>
            <origin rpy="0 0 0" xyz="0 0 0"/>
            <geometry>
                <mesh filename="package://robot_sim_description/meshes/lf_low.stl" scale="0.001 0.001 0.001"/>
            </geometry>
            <material name="silver"/>
        </visual>
        <collision>
            <origin rpy="0 0 0" xyz="0 0 0"/>
            <geometry>
                <mesh filename="package://robot_sim_description/meshes/lf_low.stl" scale="0.001 0.001 0.001"/>
            </geometry>
        </collision>
    </link>
    <joint name="lf_foot_joint" type="fixed">
        <parent link="lf_low_link"/>
        <child link="lf_foot_link"/>
        <origin rpy="0 0 0" xyz="0 0 -0.0495"/>
    </joint>
    <link name="lf_foot_link">
        <inertial>
            <mass value="0.1"/>
            <inertia ixx="0.0001" ixy="0.0" ixz="0.0" iyy="0.0001" iyz="0.0" izz="0.0001"/>
        </inertial>
        <visual>
            <origin rpy="0 0 0" xyz="0 0 0"/>
            <geometry>
                <mesh filename="package://robot_sim_description/meshes/lf_foot.stl" scale="0.001 0.001 0.001"/>
            </geometry>
            <material name="silver"/>
        </visual>
        <collision>
            <origin rpy="0 0 0" xyz="0 0 0"/>
            <geometry>
                <sphere radius="0.02"/>
            </geometry>
        </collision>
    </link>


    <joint name="lh_hipp_joint" type="revolute">
        <axis xyz="1 0 0"/>
        <limit effort="5" lower="-3.14" upper="3.14" velocity="2.5"/>
        <parent link="base_link"/>
        <child link="lh_hipp_link"/>
        <origin rpy="0 0 0" xyz="-0.04640 0.04937 0.01767"/>
    </joint>
    <link name="lh_hipp_link">
        <inertial>
            <mass value="0.7"/>
            <inertia ixx="0.0001866" ixy="0.0" ixz="0.0" iyy="0.0001866" iyz="0.0" izz="0.0001866"/>
        </inertial>
        <visual>
            <origin rpy="0 0 0" xyz="0 0 0"/>
            <geometry>
                <mesh filename="package://robot_sim_description/meshes/lh_hipp.stl" scale="0.001 0.001 0.001"/>
            </geometry>
            <material name="silver"/>
        </visual>
        <collision>
            <origin rpy="0 0 0" xyz="0 0 0"/>
            <geometry>
                <mesh filename="package://robot_sim_description/meshes/lh_hipp.stl" scale="0.001 0.001 0.001"/>
            </geometry>
        </collision>
    </link>
    <joint name="lh_up_joint" type="revolute">
        <axis xyz="0 1 0"/>
        <limit effort="5" lower="-3.14" upper="3.14" velocity="2.5"/>
        <parent link="lh_hipp_link"/>
        <child link="lh_up_link"/>
        <origin rpy="0 0 0" xyz="0 0.0266 0"/>
    </joint>
    <link name="lh_up_link">
        <inertial>
            <origin xyz="0 0 -0.03265"/>
            <mass value="0.2"/>
            <inertia ixx="0.0000777" ixy="0.0" ixz="0.0" iyy="0.0000860" iyz="0.0" izz="0.0000216"/>
        </inertial>
        <visual>
            <origin rpy="0 0 0" xyz="0 0 0"/>
            <geometry>
                <mesh filename="package://robot_sim_description/meshes/lh_up.stl" scale="0.001 0.001 0.001"/>
            </geometry>
            <material name="silver"/>
        </visual>
        <collision>
            <origin rpy="0 0 0" xyz="0 0 0"/>
            <geometry>
                <mesh filename="package://robot_sim_description/meshes/lh_up.stl" scale="0.001 0.001 0.001"/>
            </geometry>
        </collision>
    </link>
    <joint name="lh_low_joint" type="revolute">
        <axis xyz="0 1 0"/>
        <limit effort="5" lower="-3.14" upper="3.14" velocity="2.5"/>
        <parent link="lh_up_link"/>
        <child link="lh_low_link"/>
        <origin rpy="0 0 0" xyz="0 0.0075 -0.0653"/>
    </joint>
    <link name="lh_low_link">
        <inertial>
            <origin xyz="0 0 -0.025"/>
            <mass value="0.2"/>
            <inertia ixx="0.0000483" ixy="0.0" ixz="0.0" iyy="0.0000483" iyz="0.0" izz="0.0000133"/>
        </inertial>
        <visual>
            <origin rpy="0 0 0" xyz="0 0 0"/>
            <geometry>
                <mesh filename="package://robot_sim_description/meshes/lh_low.stl" scale="0.001 0.001 0.001"/>
            </geometry>
            <material name="silver"/>
        </visual>
        <collision>
            <origin rpy="0 0 0" xyz="0 0 0"/>
            <geometry>
                <mesh filename="package://robot_sim_description/meshes/lh_low.stl" scale="0.001 0.001 0.001"/>
            </geometry>
        </collision>
    </link>
    <joint name="lh_foot_joint" type="fixed">
        <parent link="lh_low_link"/>
        <child link="lh_foot_link"/>
        <origin rpy="0 0 0" xyz="0 0 -0.0495"/>
    </joint>
    <link name="lh_foot_link">
        <inertial>
            <mass value="0.1"/>
            <inertia ixx="0.0001" ixy="0.0" ixz="0.0" iyy="0.0001" iyz="0.0" izz="0.0001"/>
        </inertial>
        <visual>
            <origin rpy="0 0 0" xyz="0 0 0"/>
            <geometry>
                <mesh filename="package://robot_sim_description/meshes/lh_foot.stl" scale="0.001 0.001 0.001"/>
            </geometry>
            <material name="silver"/>
        </visual>
        <collision>
            <origin rpy="0 0 0" xyz="0 0 0"/>
            <geometry>
                <sphere radius="0.02"/>
            </geometry>
        </collision>
    </link>


    <joint name="rf_hipp_joint" type="revolute">
        <axis xyz="1 0 0"/>
        <limit effort="5" lower="-3.14" upper="3.14" velocity="2.5"/>
        <parent link="base_link"/>
        <child link="rf_hipp_link"/>
        <origin rpy="0 0 0" xyz="0.04469 -0.04937 0.01767"/>
    </joint>
    <link name="rf_hipp_link">
        <inertial>
            <mass value="0.7"/>
            <inertia ixx="0.0001866" ixy="0.0" ixz="0.0" iyy="0.0001866" iyz="0.0" izz="0.0001866"/>
        </inertial>
        <visual>
            <origin rpy="0 0 0" xyz="0 0 0"/>
            <geometry>
                <mesh filename="package://robot_sim_description/meshes/rf_hipp.stl" scale="0.001 0.001 0.001"/>
            </geometry>
            <material name="silver"/>
        </visual>
        <collision>
            <origin rpy="0 0 0" xyz="0 0 0"/>
            <geometry>
                <mesh filename="package://robot_sim_description/meshes/rf_hippp.stl" scale="0.001 0.001 0.001"/>
            </geometry>
        </collision>
    </link>
    <joint name="rf_up_joint" type="revolute">
        <axis xyz="0 1 0"/>
        <limit effort="5" lower="-3.14" upper="3.14" velocity="2.5"/>
        <parent link="rf_hipp_link"/>
        <child link="rf_up_link"/>
        <origin rpy="0 0 0" xyz="0 -0.0266 0"/>
    </joint>
    <link name="rf_up_link">
        <inertial>
            <origin xyz="0 0 -0.03265"/>
            <mass value="0.2"/>
            <inertia ixx="0.0000777" ixy="0.0" ixz="0.0" iyy="0.0000860" iyz="0.0" izz="0.0000216"/>
        </inertial>
        <visual>
            <origin rpy="0 0 0" xyz="0 0 0"/>
            <geometry>
                <mesh filename="package://robot_sim_description/meshes/rf_up.stl" scale="0.001 0.001 0.001"/>
            </geometry>
            <material name="silver"/>
        </visual>
        <collision>
            <origin rpy="0 0 0" xyz="0 0 0"/>
            <geometry>
                <mesh filename="package://robot_sim_description/meshes/rf_up.stl" scale="0.001 0.001 0.001"/>
            </geometry>
        </collision>
    </link>
    <joint name="rf_low_joint" type="revolute">
        <axis xyz="0 1 0"/>
        <limit effort="5" lower="-3.14" upper="3.14" velocity="2.5"/>
        <parent link="rf_up_link"/>
        <child link="rf_low_link"/>
        <origin rpy="0 0 0" xyz="0 -0.0075 -0.0653"/>
    </joint>
    <link name="rf_low_link">
        <inertial>
            <origin xyz="0 0 -0.025"/>
            <mass value="0.2"/>
            <inertia ixx="0.0000483" ixy="0.0" ixz="0.0" iyy="0.0000483" iyz="0.0" izz="0.0000133"/>
        </inertial>
        <visual>
            <origin rpy="0 0 0" xyz="0 0 0"/>
            <geometry>
                <mesh filename="package://robot_sim_description/meshes/rf_low.stl" scale="0.001 0.001 0.001"/>
            </geometry>
            <material name="silver"/>
        </visual>
        <collision>
            <origin rpy="0 0 0" xyz="0 0 0"/>
            <geometry>
                <mesh filename="package://robot_sim_description/meshes/rf_low.stl" scale="0.001 0.001 0.001"/>
            </geometry>
        </collision>
    </link>
    <joint name="rf_foot_joint" type="fixed">
        <parent link="rf_low_link"/>
        <child link="rf_foot_link"/>
        <origin rpy="0 0 0" xyz="0 0 -0.0495"/>
    </joint>
    <link name="rf_foot_link">
        <inertial>
            <mass value="0.1"/>
            <inertia ixx="0.0001" ixy="0.0" ixz="0.0" iyy="0.0001" iyz="0.0" izz="0.0001"/>
        </inertial>
        <visual>
            <origin rpy="0 0 0" xyz="0 0 0"/>
            <geometry>
                <mesh filename="package://robot_sim_description/meshes/rf_foot.stl" scale="0.001 0.001 0.001"/>
            </geometry>
            <material name="silver"/>
        </visual>
        <collision>
            <origin rpy="0 0 0" xyz="0 0 0"/>
            <geometry>
                <sphere radius="0.02"/>
            </geometry>
        </collision>
    </link>


    <joint name="rh_hipp_joint" type="revolute">
        <axis xyz="1 0 0"/>
        <limit effort="5" lower="-3.14" upper="3.14" velocity="2.5"/>
        <parent link="base_link"/>
        <child link="rh_hipp_link"/>
        <origin rpy="0 0 0" xyz="-0.04640 -0.04937 0.01767"/>
    </joint>
    <link name="rh_hipp_link">
        <inertial>
            <mass value="0.7"/>
            <inertia ixx="0.0001866" ixy="0.0" ixz="0.0" iyy="0.0001866" iyz="0.0" izz="0.0001866"/>
        </inertial>
        <visual>
            <origin rpy="0 0 0" xyz="0 0 0"/>
            <geometry>
                <mesh filename="package://robot_sim_description/meshes/rh_hipp.stl" scale="0.001 0.001 0.001"/>
            </geometry>
            <material name="silver"/>
        </visual>
        <collision>
            <origin rpy="0 0 0" xyz="0 0 0"/>
            <geometry>
                <mesh filename="package://robot_sim_description/meshes/rh_hipp.stl" scale="0.001 0.001 0.001"/>
            </geometry>
        </collision>
    </link>
    <joint name="rh_up_joint" type="revolute">
        <axis xyz="0 1 0"/>
        <limit effort="5" lower="-3.14" upper="3.14" velocity="2.5"/>
        <parent link="rh_hipp_link"/>
        <child link="rh_up_link"/>
        <origin rpy="0 0 0" xyz="0 -0.0266 0"/>
    </joint>
    <link name="rh_up_link">
        <inertial>
            <origin xyz="0 0 -0.03265"/>
            <mass value="0.2"/>
            <inertia ixx="0.0000777" ixy="0.0" ixz="0.0" iyy="0.0000860" iyz="0.0" izz="0.0000216"/>
        </inertial>
        <visual>
            <origin rpy="0 0 0" xyz="0 0 0"/>
            <geometry>
                <mesh filename="package://robot_sim_description/meshes/rh_up.stl" scale="0.001 0.001 0.001"/>
            </geometry>
            <material name="silver"/>
        </visual>
        <collision>
            <origin rpy="0 0 0" xyz="0 0 0"/>
            <geometry>
                <mesh filename="package://robot_sim_description/meshes/rh_up.stl" scale="0.001 0.001 0.001"/>
            </geometry>
        </collision>
    </link>
    <joint name="rh_low_joint" type="revolute">
        <axis xyz="0 1 0"/>
        <limit effort="5" lower="-3.14" upper="3.14" velocity="2.5"/>
        <parent link="rh_up_link"/>
        <child link="rh_low_link"/>
        <origin rpy="0 0 0" xyz="0 -0.0075 -0.0653"/>
    </joint>
    <link name="rh_low_link">
        <inertial>
            <origin xyz="0 0 -0.025"/>
            <mass value="0.2"/>
            <inertia ixx="0.0000483" ixy="0.0" ixz="0.0" iyy="0.0000483" iyz="0.0" izz="0.0000133"/>
        </inertial>
        <visual>
            <origin rpy="0 0 0" xyz="0 0 0"/>
            <geometry>
                <mesh filename="package://robot_sim_description/meshes/rh_low.stl" scale="0.001 0.001 0.001"/>
            </geometry>
            <material name="silver"/>
        </visual>
        <collision>
            <origin rpy="0 0 0" xyz="0 0 0"/>
            <geometry>
                <mesh filename="package://robot_sim_description/meshes/rh_low.stl" scale="0.001 0.001 0.001"/>
            </geometry>
        </collision>
    </link>
    <joint name="rh_foot_joint" type="fixed">
        <parent link="rh_low_link"/>
        <child link="rh_foot_link"/>
        <origin rpy="0 0 0" xyz="0 0 -0.0495"/>
    </joint>
    <link name="rh_foot_link">
        <inertial>
            <mass value="0.1"/>
            <inertia ixx="0.0001" ixy="0.0" ixz="0.0" iyy="0.0001" iyz="0.0" izz="0.0001"/>
        </inertial>
        <visual>
            <origin rpy="0 0 0" xyz="0 0 0"/>
            <geometry>
                <mesh filename="package://robot_sim_description/meshes/rh_foot.stl" scale="0.001 0.001 0.001"/>
            </geometry>
            <material name="silver"/>
        </visual>
        <collision>
            <origin rpy="0 0 0" xyz="0 0 0"/>
            <geometry>
                <sphere radius="0.02"/>
            </geometry>
        </collision>
    </link>


    <transmission name="lf_hipp_joint_trans">
        <type>transmission_interface/SimpleTransmission</type>
        <joint name="lf_hipp_joint">
            <hardwareInterface>hardware_interface/EffortJointInterface</hardwareInterface>
        </joint>
        <actuator name="lf_hipp_joint_motor">
            <hardwareInterface>hardware_interface/EffortJointInterface</hardwareInterface>
            <mechanicalReduction>1</mechanicalReduction>
        </actuator>
    </transmission>
    <transmission name="lf_up_joint_trans">
        <type>transmission_interface/SimpleTransmission</type>
        <joint name="lf_up_joint">
            <hardwareInterface>hardware_interface/EffortJointInterface</hardwareInterface>
        </joint>
        <actuator name="lf_up_joint_motor">
            <hardwareInterface>hardware_interface/EffortJointInterface</hardwareInterface>
            <mechanicalReduction>1</mechanicalReduction>
        </actuator>
    </transmission>
    <transmission name="lf_low_joint_trans">
        <type>transmission_interface/SimpleTransmission</type>
        <joint name="lf_low_joint">
            <hardwareInterface>hardware_interface/EffortJointInterface</hardwareInterface>
        </joint>
        <actuator name="lf_low_joint_motor">
            <hardwareInterface>hardware_interface/EffortJointInterface</hardwareInterface>
            <mechanicalReduction>1</mechanicalReduction>
        </actuator>
    </transmission>

    <transmission name="lh_hipp_joint_trans">
        <type>transmission_interface/SimpleTransmission</type>
        <joint name="lh_hipp_joint">
            <hardwareInterface>hardware_interface/EffortJointInterface</hardwareInterface>
        </joint>
        <actuator name="lh_hipp_joint_motor">
            <hardwareInterface>hardware_interface/EffortJointInterface</hardwareInterface>
            <mechanicalReduction>1</mechanicalReduction>
        </actuator>
    </transmission>
    <transmission name="lh_up_joint_trans">
        <type>transmission_interface/SimpleTransmission</type>
        <joint name="lh_up_joint">
            <hardwareInterface>hardware_interface/EffortJointInterface</hardwareInterface>
        </joint>
        <actuator name="lh_up_joint_motor">
            <hardwareInterface>hardware_interface/EffortJointInterface</hardwareInterface>
            <mechanicalReduction>1</mechanicalReduction>
        </actuator>
    </transmission>
    <transmission name="lh_low_joint_trans">
        <type>transmission_interface/SimpleTransmission</type>
        <joint name="lh_low_joint">
            <hardwareInterface>hardware_interface/EffortJointInterface</hardwareInterface>
        </joint>
        <actuator name="lh_low_joint_motor">
            <hardwareInterface>hardware_interface/EffortJointInterface</hardwareInterface>
            <mechanicalReduction>1</mechanicalReduction>
        </actuator>
    </transmission>

    <transmission name="rf_hipp_joint_trans">
        <type>transmission_interface/SimpleTransmission</type>
        <joint name="rf_hipp_joint">
            <hardwareInterface>hardware_interface/EffortJointInterface</hardwareInterface>
        </joint>
        <actuator name="rf_hipp_joint_motor">
            <hardwareInterface>hardware_interface/EffortJointInterface</hardwareInterface>
            <mechanicalReduction>1</mechanicalReduction>
        </actuator>
    </transmission>
    <transmission name="rf_up_joint_trans">
        <type>transmission_interface/SimpleTransmission</type>
        <joint name="rf_up_joint">
            <hardwareInterface>hardware_interface/EffortJointInterface</hardwareInterface>
        </joint>
        <actuator name="rf_up_joint_motor">
            <hardwareInterface>hardware_interface/EffortJointInterface</hardwareInterface>
            <mechanicalReduction>1</mechanicalReduction>
        </actuator>
    </transmission>
    <transmission name="rf_low_joint_trans">
        <type>transmission_interface/SimpleTransmission</type>
        <joint name="rf_low_joint">
            <hardwareInterface>hardware_interface/EffortJointInterface</hardwareInterface>
        </joint>
        <actuator name="rf_low_joint_motor">
            <hardwareInterface>hardware_interface/EffortJointInterface</hardwareInterface>
            <mechanicalReduction>1</mechanicalReduction>
        </actuator>
    </transmission>

    <transmission name="rh_hipp_joint_trans">
        <type>transmission_interface/SimpleTransmission</type>
        <joint name="rh_hipp_joint">
            <hardwareInterface>hardware_interface/EffortJointInterface</hardwareInterface>
        </joint>
        <actuator name="rh_hipp_joint_motor">
            <hardwareInterface>hardware_interface/EffortJointInterface</hardwareInterface>
            <mechanicalReduction>1</mechanicalReduction>
        </actuator>
    </transmission>
    <transmission name="rh_up_joint_trans">
        <type>transmission_interface/SimpleTransmission</type>
        <joint name="rh_up_joint">
            <hardwareInterface>hardware_interface/EffortJointInterface</hardwareInterface>
        </joint>
        <actuator name="rh_up_joint_motor">
            <hardwareInterface>hardware_interface/EffortJointInterface</hardwareInterface>
            <mechanicalReduction>1</mechanicalReduction>
        </actuator>
    </transmission>
    <transmission name="rh_low_joint_trans">
        <type>transmission_interface/SimpleTransmission</type>
        <joint name="rh_low_joint">
            <hardwareInterface>hardware_interface/EffortJointInterface</hardwareInterface>
        </joint>
        <actuator name="rh_low_joint_motor">
            <hardwareInterface>hardware_interface/EffortJointInterface</hardwareInterface>
            <mechanicalReduction>1</mechanicalReduction>
        </actuator>
    </transmission>

    <gazebo>
        <plugin filename="libgazebo_ros_p3d.so" name="p3d_base_controller">
            <alwaysOn>true</alwaysOn>
            <updateRate>10.0</updateRate>
            <bodyName>base_link</bodyName>
            <topicName>odom/ground_truth</topicName>
            <gaussianNoise>0.01</gaussianNoise>
            <frameName>world</frameName>
            <xyzOffsets>0 0 0</xyzOffsets>
            <rpyOffsets>0 0 0</rpyOffsets>
        </plugin>
    </gazebo>

    <gazebo>
        <plugin filename="libgazebo_ros_control.so" name="gazebo_ros_control">
            <legacyModeNS>true</legacyModeNS>
        </plugin>
    </gazebo>

</robot>